Workbook

Sheet Data
A1: Código LT | B1: Periodo | C1: Mes Izipay | D1: Fecha de Ingreso | E1: Fecha de Instalación | F1: Código | G1: Serie | H1: Ruc | I1: Razón Social | J1: Nombre Comercial | K1: Estado | L1: Estado LT | M1: Tipo de Venta | N1: Producto | O1: Tipo Cliente | P1: GPV Mensual | Q1: GPV Mensual LT | R1: Ejecutivo | S1: DNI Ejecutivo | T1: Correo Ejecutivo | U1: Categoría | V1: Zona | W1: Supervisor | X1: Jefatura | Y1: DNI Supervisor | Z1: Correo Supervisor | AA1: DNI Referido | AB1: Referido | AC1: Código DNI | AD1: CIIU | AE1: Detalle CIIU | AF1: Vol M0 | AG1: Vol QR M0 | AH1: Vol TJ M0 | AI1: Vol M1 | AJ1: Vol QR M1 | AK1: Vol TJ M1 | AL1: Vol M2 | AM1: Vol QR M2 | AN1: Vol TJ M2 | AO1: Vol M3 | AP1: Vol QR M3 | AQ1: Vol TJ M3 | AR1: Ruc Activo
A2: =CONCATENATE(Data.[[#This Row],[Código]],Data.[[#This Row],[Ruc]]) -> 105841310424714441 | B2: 46143 | C2: =IFERROR(VLOOKUP(Data.[[#This Row],[Código LT]],Reportería.[],71,0),"") | D2: =IFERROR(VLOOKUP(Data.[[#This Row],[Código]],BV!A:C,2,0),"") -> 46153 | E2: =IFERROR(VLOOKUP(Data.[[#This Row],[Código]],BV!A:C,3,0),"") -> 46160 | F2: 1058413 | G2: 233WFD870802 | H2: 10424714441 | I2: CARRION CAVERO LUIS ALBERTO | J2: LOS DULCES DE VALE | K2: =IF(Data.[[#This Row],[Tipo de Venta]]<>"POS","Atendido",IF(Data.[[#This Row],[Fecha de Instalación]]<>"","Atendido","Ingresado")) -> Atendido | L2: =Data.[[#This Row],[Estado]] -> Atendido | M2: POS | N2: =IFERROR(VLOOKUP(Data.[[#This Row],[Código LT]],Reportería.[],20,0),"") | O2: =IFERROR(VLOOKUP(Data.[[#This Row],[Código LT]],Reportería.[],5,0),"") | P2: =Data.[[#This Row],[GPV Mensual LT]]/COUNTIFS(H:H,Data.[[#This Row],[Ruc]],B:B,Data.[[#This Row],[Periodo]]) -> 60000 | Q2: 60000 | R2: Milagros Rocha | S2: =VLOOKUP(Data.[[#This Row],[Ejecutivo]],Productividad!D:N,11,0) -> 43661391 | T2: =VLOOKUP(Data.[[#This Row],[DNI Ejecutivo]],Productividad!C:U,8,0) -> mrochar@lozapay.com.pe | U2: =VLOOKUP(Data.[[#This Row],[DNI Ejecutivo]],Productividad!C:U,4,0) -> Elite | V2: =IFERROR(VLOOKUP(Data.[[#This Row],[DNI Ejecutivo]],Ejecutivos.[],11,0),"") -> Lima Palomino | W2: Carlos Palomino | X2: {=IFERROR(_xlfn.IFS(Data.[[#This Row],[Supervisor]]="Jonathan Lapoint","Norte",Data.[[#This Row],[Supervisor]]="Jorge Fuentes","Norte"),"Lima")} -> Lima | Y2: =VLOOKUP(Data.[[#This Row],[Supervisor]],Ejecutivos!B:S,17,0) -> 41718975 | Z2: =VLOOKUP(Data.[[#This Row],[DNI Supervisor]],Productividad!C:U,8,0) -> carlos.palomino@lozapay.com.pe | AB2: MILAGROS EVELYN ROCHA RODRIGUEZ | AC2: =IFERROR(CONCATENATE(Data.[[#This Row],[DNI Ejecutivo]],Data.[[#This Row],[Periodo]]),"") -> 4366139146143 | AD2: =IFERROR(VLOOKUP(Data.[[#This Row],[Código LT]],Reportería.[],10,0),"") | AE2: =IFERROR(VLOOKUP(Data.[[#This Row],[Código LT]],Reportería.[],11,0),"") | AF2: 1150.6 | AI2: =IF(TEXT(Data.[[#This Row],[Periodo]],"mmm-yy")="may-26",VLOOKUP(Data.[[#This Row],[Código]],Reportería!A:BV,57,0),0) -> 0 | AL2: =IF(Data.[[#This Row],[Vol M0]]="",0,0) -> 0 | AM2: =IF(Data.[[#This Row],[Vol M0]]="",0,0) -> 0 | AN2: =IF(Data.[[#This Row],[Vol M0]]="",0,0) -> 0 | AO2: =IF(Data.[[#This Row],[Vol M0]]="",0,0) -> 0 | AP2: =IF(Data.[[#This Row],[Vol M0]]="",0,0) -> 0 | AQ2: =IF(Data.[[#This Row],[Vol M0]]="",0,0) -> 0 | AR2: =IFERROR(IF(OR(AND(OR(Data.[[#This Row],[Categoría]]="Hunter",Data.[[#This Row],[Categoría]]="Senior"),OR(SUMIFS(AF:AF,H:H,Data.[[#This Row],[Ruc]],B:B,Data.[[#This Row],[Periodo]])>=15000,SUMIFS(AI:AI,H:H,Data.[[#This Row],[Ruc]],B:B,Data.[[#This Row],[Periodo]])>=15000,SUMIFS(AL:AL,H:H,Data.[[#This Row],[Ruc]],B:B,Data.[[#This Row],[Periodo]])>=15000,SUMIFS(AO:AO,H:H,Data.[[#This Row],[Ruc]],B:B,Data.[[#This Row],[Periodo]])>=15000)),AND(Data.[[#This Row],[Categoría]]="Elite",OR(SUMIFS(AF:AF,H:H,Data.[[#This Row],[Ruc]],B:B,Data.[[#This Row],[Periodo]])>=25000,SUMIFS(AI:AI,H:H,Data.[[#This Row],[Ruc]],B:B,Data.[[#This Row],[Periodo]])>=25000,SUMIFS(AL:AL,H:H,Data.[[#This Row],[Ruc]],B:B,Data.[[#This Row],[Periodo]])>=25000,SUMIFS(AO:AO,H:H,Data.[[#This Row],[Ruc]],B:B,Data.[[#This Row],[Periodo]])>=25000))),1,0)/COUNTIFS(H:H,Data.[[#This Row],[Ruc]],B:B,Data.[[#This Row],[Periodo]]),0) -> 0
A3: =CONCATENATE(Data.[[#This Row],[Código]],Data.[[#This Row],[Ruc]]) -> 594666620533799401 | B3: 46143 | C3: =IFERROR(VLOOKUP(Data.[[#This Row],[Código LT]],Reportería.[],71,0),"") | D3: =IFERROR(VLOOKUP(Data.[[#This Row],[Código]],BV!A:C,2,0),"") -> 46153 | E3: =IFERROR(VLOOKUP(Data.[[#This Row],[Código]],BV!A:C,3,0),"") -> 46157 | F3: 5946666 | G3: TJ33261A20815 | H3: 20533799401 | I3: PRB CORPORATION S.R.L. | J3: DISCOBAR | K3: =IF(Data.[[#This Row],[Tipo de Venta]]<>"POS","Atendido",IF(Data.[[#This Row],[Fecha de Instalación]]<>"","Atendido","Ingresado")) -> Atendido | L3: =Data.[[#This Row],[Estado]] -> Atendido | M3: POS | N3: =IFERROR(VLOOKUP(Data.[[#This Row],[Código LT]],Reportería.[],20,0),"") | O3: =IFERROR(VLOOKUP(Data.[[#This Row],[Código LT]],Reportería.[],5,0),"") | P3: =Data.[[#This Row],[GPV Mensual LT]]/COUNTIFS(H:H,Data.[[#This Row],[Ruc]],B:B,Data.[[#This Row],[Periodo]]) -> 112500 | Q3: 225000 | R3: Jose Mujica | S3: =VLOOKUP(Data.[[#This Row],[Ejecutivo]],Productividad!D:N,11,0) -> 002409208 | T3: =VLOOKUP(Data.[[#This Row],[DNI Ejecutivo]],Productividad!C:U,8,0) -> jose.mujica@lozapay.com.pe | U3: =VLOOKUP(Data.[[#This Row],[DNI Ejecutivo]],Productividad!C:U,4,0) -> Senior | V3: =IFERROR(VLOOKUP(Data.[[#This Row],[DNI Ejecutivo]],Ejecutivos.[],11,0),"") -> Norte Fuentes | W3: Jorge Fuentes | X3: {=IFERROR(_xlfn.IFS(Data.[[#This Row],[Supervisor]]="Jonathan Lapoint","Norte",Data.[[#This Row],[Supervisor]]="Jorge Fuentes","Norte"),"Lima")} -> Norte | Y3: =VLOOKUP(Data.[[#This Row],[Supervisor]],Ejecutivos!B:S,17,0) -> 70059865 | Z3: =VLOOKUP(Data.[[#This Row],[DNI Supervisor]],Productividad!C:U,8,0) -> jfuentes@lozapay.com.pe | AB3: JOSE GREGORIO MUJICA RUIZ | AC3: =IFERROR(CONCATENATE(Data.[[#This Row],[DNI Ejecutivo]],Data.[[#This Row],[Periodo]]),"") -> 00240920846143 | AD3: =IFERROR(VLOOKUP(Data.[[#This Row],[Código LT]],Reportería.[],10,0),"") | AE3: =IFERROR(VLOOKUP(Data.[[#This Row],[Código LT]],Reportería.[],11,0),"") | AF3: 28136 | AI3: =IF(TEXT(Data.[[#This Row],[Periodo]],"mmm-yy")="may-26",VLOOKUP(Data.[[#This Row],[Código]],Reportería!A:BV,57,0),0) -> 16342 | AL3: =IF(Data.[[#This Row],[Vol M0]]="",0,0) -> 0 | AM3: =IF(Data.[[#This Row],[Vol M0]]="",0,0) -> 0 | AN3: =IF(Data.[[#This Row],[Vol M0]]="",0,0) -> 0 | AO3: =IF(Data.[[#This Row],[Vol M0]]="",0,0) -> 0 | AP3: =IF(Data.[[#This Row],[Vol M0]]="",0,0) -> 0 | AQ3: =IF(Data.[[#This Row],[Vol M0]]="",0,0) -> 0 | AR3: =IFERROR(IF(OR(AND(OR(Data.[[#This Row],[Categoría]]="Hunter",Data.[[#This Row],[Categoría]]="Senior"),OR(SUMIFS(AF:AF,H:H,Data.[[#This Row],[Ruc]],B:B,Data.[[#This Row],[Periodo]])>=15000,SUMIFS(AI:AI,H:H,Data.[[#This Row],[Ruc]],B:B,Data.[[#This Row],[Periodo]])>=15000,SUMIFS(AL:AL,H:H,Data.[[#This Row],[Ruc]],B:B,Data.[[#This Row],[Periodo]])>=15000,SUMIFS(AO:AO,H:H,Data.[[#This Row],[Ruc]],B:B,Data.[[#This Row],[Periodo]])>=15000)),AND(Data.[[#This Row],[Categoría]]="Elite",OR(SUMIFS(AF:AF,H:H,Data.[[#This Row],[Ruc]],B:B,Data.[[#This Row],[Periodo]])>=25000,SUMIFS(AI:AI,H:H,Data.[[#This Row],[Ruc]],B:B,Data.[[#This Row],[Periodo]])>=25000,SUMIFS(AL:AL,H:H,Data.[[#This Row],[Ruc]],B:B,Data.[[#This Row],[Periodo]])>=25000,SUMIFS(AO:AO,H:H,Data.[[#This Row],[Ruc]],B:B,Data.[[#This Row],[Periodo]])>=25000))),1,0)/COUNTIFS(H:H,Data.[[#This Row],[Ruc]],B:B,Data.[[#This Row],[Periodo]]),0) -> 0.5
A4: =CONCATENATE(Data.[[#This Row],[Código]],Data.[[#This Row],[Ruc]]) -> 594637720533799401 | B4: 46143 | C4: =IFERROR(VLOOKUP(Data.[[#This Row],[Código LT]],Reportería.[],71,0),"") | D4: =IFERROR(VLOOKUP(Data.[[#This Row],[Código]],BV!A:C,2,0),"") -> 46153 | E4: =IFERROR(VLOOKUP(Data.[[#This Row],[Código]],BV!A:C,3,0),"") -> 46157 | F4: 5946377 | G4: TJ33261C21711 | H4: 20533799401 | I4: PRB CORPORATION S.R.L. | J4: DISCOBAR | K4: =IF(Data.[[#This Row],[Tipo de Venta]]<>"POS","Atendido",IF(Data.[[#This Row],[Fecha de Instalación]]<>"","Atendido","Ingresado")) -> Atendido | L4: =Data.[[#This Row],[Estado]] -> Atendido | M4: POS | N4: =IFERROR(VLOOKUP(Data.[[#This Row],[Código LT]],Reportería.[],20,0),"") | O4: =IFERROR(VLOOKUP(Data.[[#This Row],[Código LT]],Reportería.[],5,0),"") | P4: =Data.[[#This Row],[GPV Mensual LT]]/COUNTIFS(H:H,Data.[[#This Row],[Ruc]],B:B,Data.[[#This Row],[Periodo]]) -> 112500 | Q4: 225000 | R4: Jose Mujica | S4: =VLOOKUP(Data.[[#This Row],[Ejecutivo]],Productividad!D:N,11,0) -> 002409208 | T4: =VLOOKUP(Data.[[#This Row],[DNI Ejecutivo]],Productividad!C:U,8,0) -> jose.mujica@lozapay.com.pe | U4: =VLOOKUP(Data.[[#This Row],[DNI Ejecutivo]],Productividad!C:U,4,0) -> Senior | V4: =IFERROR(VLOOKUP(Data.[[#This Row],[DNI Ejecutivo]],Ejecutivos.[],11,0),"") -> Norte Fuentes | W4: Jorge Fuentes | X4: {=IFERROR(_xlfn.IFS(Data.[[#This Row],[Supervisor]]="Jonathan Lapoint","Norte",Data.[[#This Row],[Supervisor]]="Jorge Fuentes","Norte"),"Lima")} -> Norte | Y4: =VLOOKUP(Data.[[#This Row],[Supervisor]],Ejecutivos!B:S,17,0) -> 70059865 | Z4: =VLOOKUP(Data.[[#This Row],[DNI Supervisor]],Productividad!C:U,8,0) -> jfuentes@lozapay.com.pe | AB4: JOSE GREGORIO MUJICA RUIZ | AC4: =IFERROR(CONCATENATE(Data.[[#This Row],[DNI Ejecutivo]],Data.[[#This Row],[Periodo]]),"") -> 00240920846143 | AD4: =IFERROR(VLOOKUP(Data.[[#This Row],[Código LT]],Reportería.[],10,0),"") | AE4: =IFERROR(VLOOKUP(Data.[[#This Row],[Código LT]],Reportería.[],11,0),"") | AF4: 19372 | AI4: =IF(TEXT(Data.[[#This Row],[Periodo]],"mmm-yy")="may-26",VLOOKUP(Data.[[#This Row],[Código]],Reportería!A:BV,57,0),0) -> 15326 | AL4: =IF(Data.[[#This Row],[Vol M0]]="",0,0) -> 0 | AM4: =IF(Data.[[#This Row],[Vol M0]]="",0,0) -> 0 | AN4: =IF(Data.[[#This Row],[Vol M0]]="",0,0) -> 0 | AO4: =IF(Data.[[#This Row],[Vol M0]]="",0,0) -> 0 | AP4: =IF(Data.[[#This Row],[Vol M0]]="",0,0) -> 0 | AQ4: =IF(Data.[[#This Row],[Vol M0]]="",0,0) -> 0 | AR4: =IFERROR(IF(OR(AND(OR(Data.[[#This Row],[Categoría]]="Hunter",Data.[[#This Row],[Categoría]]="Senior"),OR(SUMIFS(AF:AF,H:H,Data.[[#This Row],[Ruc]],B:B,Data.[[#This Row],[Periodo]])>=15000,SUMIFS(AI:AI,H:H,Data.[[#This Row],[Ruc]],B:B,Data.[[#This Row],[Periodo]])>=15000,SUMIFS(AL:AL,H:H,Data.[[#This Row],[Ruc]],B:B,Data.[[#This Row],[Periodo]])>=15000,SUMIFS(AO:AO,H:H,Data.[[#This Row],[Ruc]],B:B,Data.[[#This Row],[Periodo]])>=15000)),AND(Data.[[#This Row],[Categoría]]="Elite",OR(SUMIFS(AF:AF,H:H,Data.[[#This Row],[Ruc]],B:B,Data.[[#This Row],[Periodo]])>=25000,SUMIFS(AI:AI,H:H,Data.[[#This Row],[Ruc]],B:B,Data.[[#This Row],[Periodo]])>=25000,SUMIFS(AL:AL,H:H,Data.[[#This Row],[Ruc]],B:B,Data.[[#This Row],[Periodo]])>=25000,SUMIFS(AO:AO,H:H,Data.[[#This Row],[Ruc]],B:B,Data.[[#This Row],[Periodo]])>=25000))),1,0)/COUNTIFS(H:H,Data.[[#This Row],[Ruc]],B:B,Data.[[#This Row],[Periodo]]),0) -> 0.5
A5: =CONCATENATE(Data.[[#This Row],[Código]],Data.[[#This Row],[Ruc]]) -> 105849820612897949 | B5: 46143 | C5: =IFERROR(VLOOKUP(Data.[[#This Row],[Código LT]],Reportería.[],71,0),"") | D5: =IFERROR(VLOOKUP(Data.[[#This Row],[Código]],BV!A:C,2,0),"") -> 46154 | E5: =IFERROR(VLOOKUP(Data.[[#This Row],[Código]],BV!A:C,3,0),"") -> 46163 | F5: 1058498 | H5: 20612897949 | I5: MIAMI IMPORT RM S.A.C. | J5: MIAMI IMPORT RM | K5: =IF(Data.[[#This Row],[Tipo de Venta]]<>"POS","Atendido",IF(Data.[[#This Row],[Fecha de Instalación]]<>"","Atendido","Ingresado")) -> Atendido | L5: =Data.[[#This Row],[Estado]] -> Atendido | M5: POS | N5: =IFERROR(VLOOKUP(Data.[[#This Row],[Código LT]],Reportería.[],20,0),"") | O5: =IFERROR(VLOOKUP(Data.[[#This Row],[Código LT]],Reportería.[],5,0),"") | P5: =Data.[[#This Row],[GPV Mensual LT]]/COUNTIFS(H:H,Data.[[#This Row],[Ruc]],B:B,Data.[[#This Row],[Periodo]]) -> 100000 | Q5: 100000 | R5: Jackeline Matos | S5: =VLOOKUP(Data.[[#This Row],[Ejecutivo]],Productividad!D:N,11,0) -> 44881019 | T5: =VLOOKUP(Data.[[#This Row],[DNI Ejecutivo]],Productividad!C:U,8,0) -> jackeline.matos@lozapay.com.pe | U5: =VLOOKUP(Data.[[#This Row],[DNI Ejecutivo]],Productividad!C:U,4,0) -> Senior | V5: =IFERROR(VLOOKUP(Data.[[#This Row],[DNI Ejecutivo]],Ejecutivos.[],11,0),"") -> Lima Hamm | W5: Hamm Ramirez | X5: {=IFERROR(_xlfn.IFS(Data.[[#This Row],[Supervisor]]="Jonathan Lapoint","Norte",Data.[[#This Row],[Supervisor]]="Jorge Fuentes","Norte"),"Lima")} -> Lima | Y5: =VLOOKUP(Data.[[#This Row],[Supervisor]],Ejecutivos!B:S,17,0) -> 44818200 | Z5: =VLOOKUP(Data.[[#This Row],[DNI Supervisor]],Productividad!C:U,8,0) -> hramirezp@lozapay.com.pe | AB5: JACKELINE SOLANGE MATOS QUIÑONES | AC5: =IFERROR(CONCATENATE(Data.[[#This Row],[DNI Ejecutivo]],Data.[[#This Row],[Periodo]]),"") -> 4488101946143 | AD5: =IFERROR(VLOOKUP(Data.[[#This Row],[Código LT]],Reportería.[],10,0),"") | AE5: =IFERROR(VLOOKUP(Data.[[#This Row],[Código LT]],Reportería.[],11,0),"") | AF5: 2505 | AI5: =IF(TEXT(Data.[[#This Row],[Periodo]],"mmm-yy")="may-26",VLOOKUP(Data.[[#This Row],[Código]],Reportería!A:BV,57,0),0) -> 27810 | AL5: =IF(Data.[[#This Row],[Vol M0]]="",0,0) -> 0 | AM5: =IF(Data.[[#This Row],[Vol M0]]="",0,0) -> 0 | AN5: =IF(Data.[[#This Row],[Vol M0]]="",0,0) -> 0 | AO5: =IF(Data.[[#This Row],[Vol M0]]="",0,0) -> 0 | AP5: =IF(Data.[[#This Row],[Vol M0]]="",0,0) -> 0 | AQ5: =IF(Data.[[#This Row],[Vol M0]]="",0,0) -> 0 | AR5: =IFERROR(IF(OR(AND(OR(Data.[[#This Row],[Categoría]]="Hunter",Data.[[#This Row],[Categoría]]="Senior"),OR(SUMIFS(AF:AF,H:H,Data.[[#This Row],[Ruc]],B:B,Data.[[#This Row],[Periodo]])>=15000,SUMIFS(AI:AI,H:H,Data.[[#This Row],[Ruc]],B:B,Data.[[#This Row],[Periodo]])>=15000,SUMIFS(AL:AL,H:H,Data.[[#This Row],[Ruc]],B:B,Data.[[#This Row],[Periodo]])>=15000,SUMIFS(AO:AO,H:H,Data.[[#This Row],[Ruc]],B:B,Data.[[#This Row],[Periodo]])>=15000)),AND(Data.[[#This Row],[Categoría]]="Elite",OR(SUMIFS(AF:AF,H:H,Data.[[#This Row],[Ruc]],B:B,Data.[[#This Row],[Periodo]])>=25000,SUMIFS(AI:AI,H:H,Data.[[#This Row],[Ruc]],B:B,Data.[[#This Row],[Periodo]])>=25000,SUMIFS(AL:AL,H:H,Data.[[#This Row],[Ruc]],B:B,Data.[[#This Row],[Periodo]])>=25000,SUMIFS(AO:AO,H:H,Data.[[#This Row],[Ruc]],B:B,Data.[[#This Row],[Periodo]])>=25000))),1,0)/COUNTIFS(H:H,Data.[[#This Row],[Ruc]],B:B,Data.[[#This Row],[Periodo]]),0) -> 1
A6: =CONCATENATE(Data.[[#This Row],[Código]],Data.[[#This Row],[Ruc]]) -> 105844120610935932 | B6: 46143 | C6: =IFERROR(VLOOKUP(Data.[[#This Row],[Código LT]],Reportería.[],71,0),"") | D6: =IFERROR(VLOOKUP(Data.[[#This Row],[Código]],BV!A:C,2,0),"") -> 46154 | E6: =IFERROR(VLOOKUP(Data.[[#This Row],[Código]],BV!A:C,3,0),"") -> 46161 | F6: 1058441 | H6: 20610935932 | I6: SERVICIOS GENERALES OPTIMAX E.I.R.L. | J6: SERVICIOS GENERALES OPTIMAX (CA TENIENTE FERRE 112 TDA D) | K6: =IF(Data.[[#This Row],[Tipo de Venta]]<>"POS","Atendido",IF(Data.[[#This Row],[Fecha de Instalación]]<>"","Atendido","Ingresado")) -> Atendido | L6: =Data.[[#This Row],[Estado]] -> Atendido | M6: POS | N6: =IFERROR(VLOOKUP(Data.[[#This Row],[Código LT]],Reportería.[],20,0),"") | O6: =IFERROR(VLOOKUP(Data.[[#This Row],[Código LT]],Reportería.[],5,0),"") | P6: =Data.[[#This Row],[GPV Mensual LT]]/COUNTIFS(H:H,Data.[[#This Row],[Ruc]],B:B,Data.[[#This Row],[Periodo]]) -> 40000 | Q6: 240000 | R6: Antoni Sifuentes | S6: =VLOOKUP(Data.[[#This Row],[Ejecutivo]],Productividad!D:N,11,0) -> 47045287 | T6: =VLOOKUP(Data.[[#This Row],[DNI Ejecutivo]],Productividad!C:U,8,0) -> asifuentesu@lozapay.com.pe | U6: =VLOOKUP(Data.[[#This Row],[DNI Ejecutivo]],Productividad!C:U,4,0) -> Elite | V6: =IFERROR(VLOOKUP(Data.[[#This Row],[DNI Ejecutivo]],Ejecutivos.[],11,0),"") -> Norte Fuentes | W6: Jorge Fuentes | X6: {=IFERROR(_xlfn.IFS(Data.[[#This Row],[Supervisor]]="Jonathan Lapoint","Norte",Data.[[#This Row],[Supervisor]]="Jorge Fuentes","Norte"),"Lima")} -> Norte | Y6: =VLOOKUP(Data.[[#This Row],[Supervisor]],Ejecutivos!B:S,17,0) -> 70059865 | Z6: =VLOOKUP(Data.[[#This Row],[DNI Supervisor]],Productividad!C:U,8,0) -> jfuentes@lozapay.com.pe | AB6: EDINSON WILLIAMS CHUYES ALDANA | AC6: =IFERROR(CONCATENATE(Data.[[#This Row],[DNI Ejecutivo]],Data.[[#This Row],[Periodo]]),"") -> 4704528746143 | AD6: =IFERROR(VLOOKUP(Data.[[#This Row],[Código LT]],Reportería.[],10,0),"") | AE6: =IFERROR(VLOOKUP(Data.[[#This Row],[Código LT]],Reportería.[],11,0),"") | AF6: 1799.2 | AI6: =IF(TEXT(Data.[[#This Row],[Periodo]],"mmm-yy")="may-26",VLOOKUP(Data.[[#This Row],[Código]],Reportería!A:BV,57,0),0) -> 4323.5 | AL6: =IF(Data.[[#This Row],[Vol M0]]="",0,0) -> 0 | AM6: =IF(Data.[[#This Row],[Vol M0]]="",0,0) -> 0 | AN6: =IF(Data.[[#This Row],[Vol M0]]="",0,0) -> 0 | AO6: =IF(Data.[[#This Row],[Vol M0]]="",0,0) -> 0 | AP6: =IF(Data.[[#This Row],[Vol M0]]="",0,0) -> 0 | AQ6: =IF(Data.[[#This Row],[Vol M0]]="",0,0) -> 0 | AR6: =IFERROR(IF(OR(AND(OR(Data.[[#This Row],[Categoría]]="Hunter",Data.[[#This Row],[Categoría]]="Senior"),OR(SUMIFS(AF:AF,H:H,Data.[[#This Row],[Ruc]],B:B,Data.[[#This Row],[Periodo]])>=15000,SUMIFS(AI:AI,H:H,Data.[[#This Row],[Ruc]],B:B,Data.[[#This Row],[Periodo]])>=15000,SUMIFS(AL:AL,H:H,Data.[[#This Row],[Ruc]],B:B,Data.[[#This Row],[Periodo]])>=15000,SUMIFS(AO:AO,H:H,Data.[[#This Row],[Ruc]],B:B,Data.[[#This Row],[Periodo]])>=15000)),AND(Data.[[#This Row],[Categoría]]="Elite",OR(SUMIFS(AF:AF,H:H,Data.[[#This Row],[Ruc]],B:B,Data.[[#This Row],[Periodo]])>=25000,SUMIFS(AI:AI,H:H,Data.[[#This Row],[Ruc]],B:B,Data.[[#This Row],[Periodo]])>=25000,SUMIFS(AL:AL,H:H,Data.[[#This Row],[Ruc]],B:B,Data.[[#This Row],[Periodo]])>=25000,SUMIFS(AO:AO,H:H,Data.[[#This Row],[Ruc]],B:B,Data.[[#This Row],[Periodo]])>=25000))),1,0)/COUNTIFS(H:H,Data.[[#This Row],[Ruc]],B:B,Data.[[#This Row],[Periodo]]),0) -> 0.16666667
A7: =CONCATENATE(Data.[[#This Row],[Código]],Data.[[#This Row],[Ruc]]) -> 105845720610935932 | B7: 46143 | C7: =IFERROR(VLOOKUP(Data.[[#This Row],[Código LT]],Reportería.[],71,0),"") | D7: =IFERROR(VLOOKUP(Data.[[#This Row],[Código]],BV!A:C,2,0),"") -> 46154 | E7: =IFERROR(VLOOKUP(Data.[[#This Row],[Código]],BV!A:C,3,0),"") -> 46161 | F7: 1058457 | H7: 20610935932 | I7: SERVICIOS GENERALES OPTIMAX E.I.R.L. | J7: SERVICIOS GENERALES OPTIMAX (CA ELIAS AGUIRRE 320 TDA 1) | K7: =IF(Data.[[#This Row],[Tipo de Venta]]<>"POS","Atendido",IF(Data.[[#This Row],[Fecha de Instalación]]<>"","Atendido","Ingresado")) -> Atendido | L7: =Data.[[#This Row],[Estado]] -> Atendido | M7: POS | N7: =IFERROR(VLOOKUP(Data.[[#This Row],[Código LT]],Reportería.[],20,0),"") | O7: =IFERROR(VLOOKUP(Data.[[#This Row],[Código LT]],Reportería.[],5,0),"") | P7: =Data.[[#This Row],[GPV Mensual LT]]/COUNTIFS(H:H,Data.[[#This Row],[Ruc]],B:B,Data.[[#This Row],[Periodo]]) -> 40000 | Q7: 240000 | R7: Antoni Sifuentes | S7: =VLOOKUP(Data.[[#This Row],[Ejecutivo]],Productividad!D:N,11,0) -> 47045287 | T7: =VLOOKUP(Data.[[#This Row],[DNI Ejecutivo]],Productividad!C:U,8,0) -> asifuentesu@lozapay.com.pe | U7: =VLOOKUP(Data.[[#This Row],[DNI Ejecutivo]],Productividad!C:U,4,0) -> Elite | V7: =IFERROR(VLOOKUP(Data.[[#This Row],[DNI Ejecutivo]],Ejecutivos.[],11,0),"") -> Norte Fuentes | W7: Jorge Fuentes | X7: {=IFERROR(_xlfn.IFS(Data.[[#This Row],[Supervisor]]="Jonathan Lapoint","Norte",Data.[[#This Row],[Supervisor]]="Jorge Fuentes","Norte"),"Lima")} -> Norte | Y7: =VLOOKUP(Data.[[#This Row],[Supervisor]],Ejecutivos!B:S,17,0) -> 70059865 | Z7: =VLOOKUP(Data.[[#This Row],[DNI Supervisor]],Productividad!C:U,8,0) -> jfuentes@lozapay.com.pe | AB7: EDINSON WILLIAMS CHUYES ALDANA | AC7: =IFERROR(CONCATENATE(Data.[[#This Row],[DNI Ejecutivo]],Data.[[#This Row],[Periodo]]),"") -> 4704528746143 | AD7: =IFERROR(VLOOKUP(Data.[[#This Row],[Código LT]],Reportería.[],10,0),"") | AE7: =IFERROR(VLOOKUP(Data.[[#This Row],[Código LT]],Reportería.[],11,0),"") | AF7: 918.9 | AI7: =IF(TEXT(Data.[[#This Row],[Periodo]],"mmm-yy")="may-26",VLOOKUP(Data.[[#This Row],[Código]],Reportería!A:BV,57,0),0) -> 3145.5 | AL7: =IF(Data.[[#This Row],[Vol M0]]="",0,0) -> 0 | AM7: =IF(Data.[[#This Row],[Vol M0]]="",0,0) -> 0 | AN7: =IF(Data.[[#This Row],[Vol M0]]="",0,0) -> 0 | AO7: =IF(Data.[[#This Row],[Vol M0]]="",0,0) -> 0 | AP7: =IF(Data.[[#This Row],[Vol M0]]="",0,0) -> 0 | AQ7: =IF(Data.[[#This Row],[Vol M0]]="",0,0) -> 0 | AR7: =IFERROR(IF(OR(AND(OR(Data.[[#This Row],[Categoría]]="Hunter",Data.[[#This Row],[Categoría]]="Senior"),OR(SUMIFS(AF:AF,H:H,Data.[[#This Row],[Ruc]],B:B,Data.[[#This Row],[Periodo]])>=15000,SUMIFS(AI:AI,H:H,Data.[[#This Row],[Ruc]],B:B,Data.[[#This Row],[Periodo]])>=15000,SUMIFS(AL:AL,H:H,Data.[[#This Row],[Ruc]],B:B,Data.[[#This Row],[Periodo]])>=15000,SUMIFS(AO:AO,H:H,Data.[[#This Row],[Ruc]],B:B,Data.[[#This Row],[Periodo]])>=15000)),AND(Data.[[#This Row],[Categoría]]="Elite",OR(SUMIFS(AF:AF,H:H,Data.[[#This Row],[Ruc]],B:B,Data.[[#This Row],[Periodo]])>=25000,SUMIFS(AI:AI,H:H,Data.[[#This Row],[Ruc]],B:B,Data.[[#This Row],[Periodo]])>=25000,SUMIFS(AL:AL,H:H,Data.[[#This Row],[Ruc]],B:B,Data.[[#This Row],[Periodo]])>=25000,SUMIFS(AO:AO,H:H,Data.[[#This Row],[Ruc]],B:B,Data.[[#This Row],[Periodo]])>=25000))),1,0)/COUNTIFS(H:H,Data.[[#This Row],[Ruc]],B:B,Data.[[#This Row],[Periodo]]),0) -> 0.16666667
A8: =CONCATENATE(Data.[[#This Row],[Código]],Data.[[#This Row],[Ruc]]) -> 105845820610935932 | B8: 46143 | C8: =IFERROR(VLOOKUP(Data.[[#This Row],[Código LT]],Reportería.[],71,0),"") | D8: =IFERROR(VLOOKUP(Data.[[#This Row],[Código]],BV!A:C,2,0),"") -> 46154 | E8: =IFERROR(VLOOKUP(Data.[[#This Row],[Código]],BV!A:C,3,0),"") -> 46161 | F8: 1058458 | H8: 20610935932 | I8: SERVICIOS GENERALES OPTIMAX E.I.R.L. | J8: SERVICIOS GENERALES OPTIMAX (CA ELIAS AGUIRRE 300 INT A) | K8: =IF(Data.[[#This Row],[Tipo de Venta]]<>"POS","Atendido",IF(Data.[[#This Row],[Fecha de Instalación]]<>"","Atendido","Ingresado")) -> Atendido | L8: =Data.[[#This Row],[Estado]] -> Atendido | M8: POS | N8: =IFERROR(VLOOKUP(Data.[[#This Row],[Código LT]],Reportería.[],20,0),"") | O8: =IFERROR(VLOOKUP(Data.[[#This Row],[Código LT]],Reportería.[],5,0),"") | P8: =Data.[[#This Row],[GPV Mensual LT]]/COUNTIFS(H:H,Data.[[#This Row],[Ruc]],B:B,Data.[[#This Row],[Periodo]]) -> 40000 | Q8: 240000 | R8: Antoni Sifuentes | S8: =VLOOKUP(Data.[[#This Row],[Ejecutivo]],Productividad!D:N,11,0) -> 47045287 | T8: =VLOOKUP(Data.[[#This Row],[DNI Ejecutivo]],Productividad!C:U,8,0) -> asifuentesu@lozapay.com.pe | U8: =VLOOKUP(Data.[[#This Row],[DNI Ejecutivo]],Productividad!C:U,4,0) -> Elite | V8: =IFERROR(VLOOKUP(Data.[[#This Row],[DNI Ejecutivo]],Ejecutivos.[],11,0),"") -> Norte Fuentes | W8: Jorge Fuentes | X8: {=IFERROR(_xlfn.IFS(Data.[[#This Row],[Supervisor]]="Jonathan Lapoint","Norte",Data.[[#This Row],[Supervisor]]="Jorge Fuentes","Norte"),"Lima")} -> Norte | Y8: =VLOOKUP(Data.[[#This Row],[Supervisor]],Ejecutivos!B:S,17,0) -> 70059865 | Z8: =VLOOKUP(Data.[[#This Row],[DNI Supervisor]],Productividad!C:U,8,0) -> jfuentes@lozapay.com.pe | AB8: EDINSON WILLIAMS CHUYES ALDANA | AC8: =IFERROR(CONCATENATE(Data.[[#This Row],[DNI Ejecutivo]],Data.[[#This Row],[Periodo]]),"") -> 4704528746143 | AD8: =IFERROR(VLOOKUP(Data.[[#This Row],[Código LT]],Reportería.[],10,0),"") | AE8: =IFERROR(VLOOKUP(Data.[[#This Row],[Código LT]],Reportería.[],11,0),"") | AF8: 6232 | AI8: =IF(TEXT(Data.[[#This Row],[Periodo]],"mmm-yy")="may-26",VLOOKUP(Data.[[#This Row],[Código]],Reportería!A:BV,57,0),0) -> 4649 | AL8: =IF(Data.[[#This Row],[Vol M0]]="",0,0) -> 0 | AM8: =IF(Data.[[#This Row],[Vol M0]]="",0,0) -> 0 | AN8: =IF(Data.[[#This Row],[Vol M0]]="",0,0) -> 0 | AO8: =IF(Data.[[#This Row],[Vol M0]]="",0,0) -> 0 | AP8: =IF(Data.[[#This Row],[Vol M0]]="",0,0) -> 0 | AQ8: =IF(Data.[[#This Row],[Vol M0]]="",0,0) -> 0 | AR8: =IFERROR(IF(OR(AND(OR(Data.[[#This Row],[Categoría]]="Hunter",Data.[[#This Row],[Categoría]]="Senior"),OR(SUMIFS(AF:AF,H:H,Data.[[#This Row],[Ruc]],B:B,Data.[[#This Row],[Periodo]])>=15000,SUMIFS(AI:AI,H:H,Data.[[#This Row],[Ruc]],B:B,Data.[[#This Row],[Periodo]])>=15000,SUMIFS(AL:AL,H:H,Data.[[#This Row],[Ruc]],B:B,Data.[[#This Row],[Periodo]])>=15000,SUMIFS(AO:AO,H:H,Data.[[#This Row],[Ruc]],B:B,Data.[[#This Row],[Periodo]])>=15000)),AND(Data.[[#This Row],[Categoría]]="Elite",OR(SUMIFS(AF:AF,H:H,Data.[[#This Row],[Ruc]],B:B,Data.[[#This Row],[Periodo]])>=25000,SUMIFS(AI:AI,H:H,Data.[[#This Row],[Ruc]],B:B,Data.[[#This Row],[Periodo]])>=25000,SUMIFS(AL:AL,H:H,Data.[[#This Row],[Ruc]],B:B,Data.[[#This Row],[Periodo]])>=25000,SUMIFS(AO:AO,H:H,Data.[[#This Row],[Ruc]],B:B,Data.[[#This Row],[Periodo]])>=25000))),1,0)/COUNTIFS(H:H,Data.[[#This Row],[Ruc]],B:B,Data.[[#This Row],[Periodo]]),0) -> 0.16666667
A9: =CONCATENATE(Data.[[#This Row],[Código]],Data.[[#This Row],[Ruc]]) -> 105845920610935932 | B9: 46143 | C9: =IFERROR(VLOOKUP(Data.[[#This Row],[Código LT]],Reportería.[],71,0),"") | D9: =IFERROR(VLOOKUP(Data.[[#This Row],[Código]],BV!A:C,2,0),"") -> 46154 | E9: =IFERROR(VLOOKUP(Data.[[#This Row],[Código]],BV!A:C,3,0),"") -> 46161 | F9: 1058459 | H9: 20610935932 | I9: SERVICIOS GENERALES OPTIMAX E.I.R.L. | J9: SERVICIOS GENERALES OPTIMAX (CA ELIAS AGUIRRE 320 TDA 4) | K9: =IF(Data.[[#This Row],[Tipo de Venta]]<>"POS","Atendido",IF(Data.[[#This Row],[Fecha de Instalación]]<>"","Atendido","Ingresado")) -> Atendido | L9: =Data.[[#This Row],[Estado]] -> Atendido | M9: POS | N9: =IFERROR(VLOOKUP(Data.[[#This Row],[Código LT]],Reportería.[],20,0),"") | O9: =IFERROR(VLOOKUP(Data.[[#This Row],[Código LT]],Reportería.[],5,0),"") | P9: =Data.[[#This Row],[GPV Mensual LT]]/COUNTIFS(H:H,Data.[[#This Row],[Ruc]],B:B,Data.[[#This Row],[Periodo]]) -> 40000 | Q9: 240000 | R9: Antoni Sifuentes | S9: =VLOOKUP(Data.[[#This Row],[Ejecutivo]],Productividad!D:N,11,0) -> 47045287 | T9: =VLOOKUP(Data.[[#This Row],[DNI Ejecutivo]],Productividad!C:U,8,0) -> asifuentesu@lozapay.com.pe | U9: =VLOOKUP(Data.[[#This Row],[DNI Ejecutivo]],Productividad!C:U,4,0) -> Elite | V9: =IFERROR(VLOOKUP(Data.[[#This Row],[DNI Ejecutivo]],Ejecutivos.[],11,0),"") -> Norte Fuentes | W9: Jorge Fuentes | X9: {=IFERROR(_xlfn.IFS(Data.[[#This Row],[Supervisor]]="Jonathan Lapoint","Norte",Data.[[#This Row],[Supervisor]]="Jorge Fuentes","Norte"),"Lima")} -> Norte | Y9: =VLOOKUP(Data.[[#This Row],[Supervisor]],Ejecutivos!B:S,17,0) -> 70059865 | Z9: =VLOOKUP(Data.[[#This Row],[DNI Supervisor]],Productividad!C:U,8,0) -> jfuentes@lozapay.com.pe | AB9: EDINSON WILLIAMS CHUYES ALDANA | AC9: =IFERROR(CONCATENATE(Data.[[#This Row],[DNI Ejecutivo]],Data.[[#This Row],[Periodo]]),"") -> 4704528746143 | AD9: =IFERROR(VLOOKUP(Data.[[#This Row],[Código LT]],Reportería.[],10,0),"") | AE9: =IFERROR(VLOOKUP(Data.[[#This Row],[Código LT]],Reportería.[],11,0),"") | AF9: 3007 | AI9: =IF(TEXT(Data.[[#This Row],[Periodo]],"mmm-yy")="may-26",VLOOKUP(Data.[[#This Row],[Código]],Reportería!A:BV,57,0),0) -> 4848 | AL9: =IF(Data.[[#This Row],[Vol M0]]="",0,0) -> 0 | AM9: =IF(Data.[[#This Row],[Vol M0]]="",0,0) -> 0 | AN9: =IF(Data.[[#This Row],[Vol M0]]="",0,0) -> 0 | AO9: =IF(Data.[[#This Row],[Vol M0]]="",0,0) -> 0 | AP9: =IF(Data.[[#This Row],[Vol M0]]="",0,0) -> 0 | AQ9: =IF(Data.[[#This Row],[Vol M0]]="",0,0) -> 0 | AR9: =IFERROR(IF(OR(AND(OR(Data.[[#This Row],[Categoría]]="Hunter",Data.[[#This Row],[Categoría]]="Senior"),OR(SUMIFS(AF:AF,H:H,Data.[[#This Row],[Ruc]],B:B,Data.[[#This Row],[Periodo]])>=15000,SUMIFS(AI:AI,H:H,Data.[[#This Row],[Ruc]],B:B,Data.[[#This Row],[Periodo]])>=15000,SUMIFS(AL:AL,H:H,Data.[[#This Row],[Ruc]],B:B,Data.[[#This Row],[Periodo]])>=15000,SUMIFS(AO:AO,H:H,Data.[[#This Row],[Ruc]],B:B,Data.[[#This Row],[Periodo]])>=15000)),AND(Data.[[#This Row],[Categoría]]="Elite",OR(SUMIFS(AF:AF,H:H,Data.[[#This Row],[Ruc]],B:B,Data.[[#This Row],[Periodo]])>=25000,SUMIFS(AI:AI,H:H,Data.[[#This Row],[Ruc]],B:B,Data.[[#This Row],[Periodo]])>=25000,SUMIFS(AL:AL,H:H,Data.[[#This Row],[Ruc]],B:B,Data.[[#This Row],[Periodo]])>=25000,SUMIFS(AO:AO,H:H,Data.[[#This Row],[Ruc]],B:B,Data.[[#This Row],[Periodo]])>=25000))),1,0)/COUNTIFS(H:H,Data.[[#This Row],[Ruc]],B:B,Data.[[#This Row],[Periodo]]),0) -> 0.16666667
A10: =CONCATENATE(Data.[[#This Row],[Código]],Data.[[#This Row],[Ruc]]) -> 105846020610935932 | B10: 46143 | C10: =IFERROR(VLOOKUP(Data.[[#This Row],[Código LT]],Reportería.[],71,0),"") | D10: =IFERROR(VLOOKUP(Data.[[#This Row],[Código]],BV!A:C,2,0),"") -> 46154 | E10: =IFERROR(VLOOKUP(Data.[[#This Row],[Código]],BV!A:C,3,0),"") -> 46161 | F10: 1058460 | H10: 20610935932 | I10: SERVICIOS GENERALES OPTIMAX E.I.R.L. | J10: SERVICIOS GENERALES OPTIMAX (CA ELIAS AGUIRRE 304-306 INT FONTE) | K10: =IF(Data.[[#This Row],[Tipo de Venta]]<>"POS","Atendido",IF(Data.[[#This Row],[Fecha de Instalación]]<>"","Atendido","Ingresado")) -> Atendido | L10: =Data.[[#This Row],[Estado]] -> Atendido | M10: POS | N10: =IFERROR(VLOOKUP(Data.[[#This Row],[Código LT]],Reportería.[],20,0),"") | O10: =IFERROR(VLOOKUP(Data.[[#This Row],[Código LT]],Reportería.[],5,0),"") | P10: =Data.[[#This Row],[GPV Mensual LT]]/COUNTIFS(H:H,Data.[[#This Row],[Ruc]],B:B,Data.[[#This Row],[Periodo]]) -> 40000 | Q10: 240000 | R10: Antoni Sifuentes | S10: =VLOOKUP(Data.[[#This Row],[Ejecutivo]],Productividad!D:N,11,0) -> 47045287 | T10: =VLOOKUP(Data.[[#This Row],[DNI Ejecutivo]],Productividad!C:U,8,0) -> asifuentesu@lozapay.com.pe | U10: =VLOOKUP(Data.[[#This Row],[DNI Ejecutivo]],Productividad!C:U,4,0) -> Elite | V10: =IFERROR(VLOOKUP(Data.[[#This Row],[DNI Ejecutivo]],Ejecutivos.[],11,0),"") -> Norte Fuentes | W10: Jorge Fuentes | X10: {=IFERROR(_xlfn.IFS(Data.[[#This Row],[Supervisor]]="Jonathan Lapoint","Norte",Data.[[#This Row],[Supervisor]]="Jorge Fuentes","Norte"),"Lima")} -> Norte | Y10: =VLOOKUP(Data.[[#This Row],[Supervisor]],Ejecutivos!B:S,17,0) -> 70059865 | Z10: =VLOOKUP(Data.[[#This Row],[DNI Supervisor]],Productividad!C:U,8,0) -> jfuentes@lozapay.com.pe | AB10: EDINSON WILLIAMS CHUYES ALDANA | AC10: =IFERROR(CONCATENATE(Data.[[#This Row],[DNI Ejecutivo]],Data.[[#This Row],[Periodo]]),"") -> 4704528746143 | AD10: =IFERROR(VLOOKUP(Data.[[#This Row],[Código LT]],Reportería.[],10,0),"") | AE10: =IFERROR(VLOOKUP(Data.[[#This Row],[Código LT]],Reportería.[],11,0),"") | AF10: 4045 | AI10: =IF(TEXT(Data.[[#This Row],[Periodo]],"mmm-yy")="may-26",VLOOKUP(Data.[[#This Row],[Código]],Reportería!A:BV,57,0),0) -> 8115.3 | AL10: =IF(Data.[[#This Row],[Vol M0]]="",0,0) -> 0 | AM10: =IF(Data.[[#This Row],[Vol M0]]="",0,0) -> 0 | AN10: =IF(Data.[[#This Row],[Vol M0]]="",0,0) -> 0 | AO10: =IF(Data.[[#This Row],[Vol M0]]="",0,0) -> 0 | AP10: =IF(Data.[[#This Row],[Vol M0]]="",0,0) -> 0 | AQ10: =IF(Data.[[#This Row],[Vol M0]]="",0,0) -> 0 | AR10: =IFERROR(IF(OR(AND(OR(Data.[[#This Row],[Categoría]]="Hunter",Data.[[#This Row],[Categoría]]="Senior"),OR(SUMIFS(AF:AF,H:H,Data.[[#This Row],[Ruc]],B:B,Data.[[#This Row],[Periodo]])>=15000,SUMIFS(AI:AI,H:H,Data.[[#This Row],[Ruc]],B:B,Data.[[#This Row],[Periodo]])>=15000,SUMIFS(AL:AL,H:H,Data.[[#This Row],[Ruc]],B:B,Data.[[#This Row],[Periodo]])>=15000,SUMIFS(AO:AO,H:H,Data.[[#This Row],[Ruc]],B:B,Data.[[#This Row],[Periodo]])>=15000)),AND(Data.[[#This Row],[Categoría]]="Elite",OR(SUMIFS(AF:AF,H:H,Data.[[#This Row],[Ruc]],B:B,Data.[[#This Row],[Periodo]])>=25000,SUMIFS(AI:AI,H:H,Data.[[#This Row],[Ruc]],B:B,Data.[[#This Row],[Periodo]])>=25000,SUMIFS(AL:AL,H:H,Data.[[#This Row],[Ruc]],B:B,Data.[[#This Row],[Periodo]])>=25000,SUMIFS(AO:AO,H:H,Data.[[#This Row],[Ruc]],B:B,Data.[[#This Row],[Periodo]])>=25000))),1,0)/COUNTIFS(H:H,Data.[[#This Row],[Ruc]],B:B,Data.[[#This Row],[Periodo]]),0) -> 0.16666667
A11: =CONCATENATE(Data.[[#This Row],[Código]],Data.[[#This Row],[Ruc]]) -> 105846220610935932 | B11: 46143 | C11: =IFERROR(VLOOKUP(Data.[[#This Row],[Código LT]],Reportería.[],71,0),"") | D11: =IFERROR(VLOOKUP(Data.[[#This Row],[Código]],BV!A:C,2,0),"") -> 46154 | E11: =IFERROR(VLOOKUP(Data.[[#This Row],[Código]],BV!A:C,3,0),"") -> 46161 | F11: 1058462 | H11: 20610935932 | I11: SERVICIOS GENERALES OPTIMAX E.I.R.L. | J11: SERVICIOS GENERALES OPTIMAX (CA ELIAS AGUIRRE 306) | K11: =IF(Data.[[#This Row],[Tipo de Venta]]<>"POS","Atendido",IF(Data.[[#This Row],[Fecha de Instalación]]<>"","Atendido","Ingresado")) -> Atendido | L11: =Data.[[#This Row],[Estado]] -> Atendido | M11: POS | N11: =IFERROR(VLOOKUP(Data.[[#This Row],[Código LT]],Reportería.[],20,0),"") | O11: =IFERROR(VLOOKUP(Data.[[#This Row],[Código LT]],Reportería.[],5,0),"") | P11: =Data.[[#This Row],[GPV Mensual LT]]/COUNTIFS(H:H,Data.[[#This Row],[Ruc]],B:B,Data.[[#This Row],[Periodo]]) -> 40000 | Q11: 240000 | R11: Antoni Sifuentes | S11: =VLOOKUP(Data.[[#This Row],[Ejecutivo]],Productividad!D:N,11,0) -> 47045287 | T11: =VLOOKUP(Data.[[#This Row],[DNI Ejecutivo]],Productividad!C:U,8,0) -> asifuentesu@lozapay.com.pe | U11: =VLOOKUP(Data.[[#This Row],[DNI Ejecutivo]],Productividad!C:U,4,0) -> Elite | V11: =IFERROR(VLOOKUP(Data.[[#This Row],[DNI Ejecutivo]],Ejecutivos.[],11,0),"") -> Norte Fuentes | W11: Jorge Fuentes | X11: {=IFERROR(_xlfn.IFS(Data.[[#This Row],[Supervisor]]="Jonathan Lapoint","Norte",Data.[[#This Row],[Supervisor]]="Jorge Fuentes","Norte"),"Lima")} -> Norte | Y11: =VLOOKUP(Data.[[#This Row],[Supervisor]],Ejecutivos!B:S,17,0) -> 70059865 | Z11: =VLOOKUP(Data.[[#This Row],[DNI Supervisor]],Productividad!C:U,8,0) -> jfuentes@lozapay.com.pe | AB11: EDINSON WILLIAMS CHUYES ALDANA | AC11: =IFERROR(CONCATENATE(Data.[[#This Row],[DNI Ejecutivo]],Data.[[#This Row],[Periodo]]),"") -> 4704528746143 | AD11: =IFERROR(VLOOKUP(Data.[[#This Row],[Código LT]],Reportería.[],10,0),"") | AE11: =IFERROR(VLOOKUP(Data.[[#This Row],[Código LT]],Reportería.[],11,0),"") | AF11: 2733 | AI11: =IF(TEXT(Data.[[#This Row],[Periodo]],"mmm-yy")="may-26",VLOOKUP(Data.[[#This Row],[Código]],Reportería!A:BV,57,0),0) -> 3942 | AL11: =IF(Data.[[#This Row],[Vol M0]]="",0,0) -> 0 | AM11: =IF(Data.[[#This Row],[Vol M0]]="",0,0) -> 0 | AN11: =IF(Data.[[#This Row],[Vol M0]]="",0,0) -> 0 | AO11: =IF(Data.[[#This Row],[Vol M0]]="",0,0) -> 0 | AP11: =IF(Data.[[#This Row],[Vol M0]]="",0,0) -> 0 | AQ11: =IF(Data.[[#This Row],[Vol M0]]="",0,0) -> 0 | AR11: =IFERROR(IF(OR(AND(OR(Data.[[#This Row],[Categoría]]="Hunter",Data.[[#This Row],[Categoría]]="Senior"),OR(SUMIFS(AF:AF,H:H,Data.[[#This Row],[Ruc]],B:B,Data.[[#This Row],[Periodo]])>=15000,SUMIFS(AI:AI,H:H,Data.[[#This Row],[Ruc]],B:B,Data.[[#This Row],[Periodo]])>=15000,SUMIFS(AL:AL,H:H,Data.[[#This Row],[Ruc]],B:B,Data.[[#This Row],[Periodo]])>=15000,SUMIFS(AO:AO,H:H,Data.[[#This Row],[Ruc]],B:B,Data.[[#This Row],[Periodo]])>=15000)),AND(Data.[[#This Row],[Categoría]]="Elite",OR(SUMIFS(AF:AF,H:H,Data.[[#This Row],[Ruc]],B:B,Data.[[#This Row],[Periodo]])>=25000,SUMIFS(AI:AI,H:H,Data.[[#This Row],[Ruc]],B:B,Data.[[#This Row],[Periodo]])>=25000,SUMIFS(AL:AL,H:H,Data.[[#This Row],[Ruc]],B:B,Data.[[#This Row],[Periodo]])>=25000,SUMIFS(AO:AO,H:H,Data.[[#This Row],[Ruc]],B:B,Data.[[#This Row],[Periodo]])>=25000))),1,0)/COUNTIFS(H:H,Data.[[#This Row],[Ruc]],B:B,Data.[[#This Row],[Periodo]]),0) -> 0.16666667
A12: =CONCATENATE(Data.[[#This Row],[Código]],Data.[[#This Row],[Ruc]]) -> 594683820615538222 | B12: 46143 | C12: =IFERROR(VLOOKUP(Data.[[#This Row],[Código LT]],Reportería.[],71,0),"") | D12: =IFERROR(VLOOKUP(Data.[[#This Row],[Código]],BV!A:C,2,0),"") -> 46154 | E12: =IFERROR(VLOOKUP(Data.[[#This Row],[Código]],BV!A:C,3,0),"") -> 46155 | F12: 5946838 | G12: TJ33261A21090 | H12: 20615538222 | I12: D & C GROUP SOLUTIONS S.A.C. | J12: D&C GROUP SOLUTIONS | K12: =IF(Data.[[#This Row],[Tipo de Venta]]<>"POS","Atendido",IF(Data.[[#This Row],[Fecha de Instalación]]<>"","Atendido","Ingresado")) -> Atendido | L12: =Data.[[#This Row],[Estado]] -> Atendido | M12: POS | N12: =IFERROR(VLOOKUP(Data.[[#This Row],[Código LT]],Reportería.[],20,0),"") | O12: =IFERROR(VLOOKUP(Data.[[#This Row],[Código LT]],Reportería.[],5,0),"") | P12: =Data.[[#This Row],[GPV Mensual LT]]/COUNTIFS(H:H,Data.[[#This Row],[Ruc]],B:B,Data.[[#This Row],[Periodo]]) -> 27000 | Q12: 27000 | R12: Richard Benites | S12: =VLOOKUP(Data.[[#This Row],[Ejecutivo]],Productividad!D:N,11,0) -> 70151010 | T12: =VLOOKUP(Data.[[#This Row],[DNI Ejecutivo]],Productividad!C:U,8,0) -> richard.benites@lozapay.com.pe | U12: =VLOOKUP(Data.[[#This Row],[DNI Ejecutivo]],Productividad!C:U,4,0) -> Hunter | V12: =IFERROR(VLOOKUP(Data.[[#This Row],[DNI Ejecutivo]],Ejecutivos.[],11,0),"") -> Lima Jean | W12: Jean Aguilar | X12: {=IFERROR(_xlfn.IFS(Data.[[#This Row],[Supervisor]]="Jonathan Lapoint","Norte",Data.[[#This Row],[Supervisor]]="Jorge Fuentes","Norte"),"Lima")} -> Lima | Y12: =VLOOKUP(Data.[[#This Row],[Supervisor]],Ejecutivos!B:S,17,0) -> 47688341 | Z12: =VLOOKUP(Data.[[#This Row],[DNI Supervisor]],Productividad!C:U,8,0) -> jaguilar@lozapay.com.pe | AB12: RICHARD PABLO BENITES JURADO | AC12: =IFERROR(CONCATENATE(Data.[[#This Row],[DNI Ejecutivo]],Data.[[#This Row],[Periodo]]),"") -> 7015101046143 | AD12: =IFERROR(VLOOKUP(Data.[[#This Row],[Código LT]],Reportería.[],10,0),"") | AE12: =IFERROR(VLOOKUP(Data.[[#This Row],[Código LT]],Reportería.[],11,0),"") | AF12: 0 | AI12: =IF(TEXT(Data.[[#This Row],[Periodo]],"mmm-yy")="may-26",VLOOKUP(Data.[[#This Row],[Código]],Reportería!A:BV,57,0),0) -> 1000 | AL12: =IF(Data.[[#This Row],[Vol M0]]="",0,0) -> 0 | AM12: =IF(Data.[[#This Row],[Vol M0]]="",0,0) -> 0 | AN12: =IF(Data.[[#This Row],[Vol M0]]="",0,0) -> 0 | AO12: =IF(Data.[[#This Row],[Vol M0]]="",0,0) -> 0 | AP12: =IF(Data.[[#This Row],[Vol M0]]="",0,0) -> 0 | AQ12: =IF(Data.[[#This Row],[Vol M0]]="",0,0) -> 0 | AR12: =IFERROR(IF(OR(AND(OR(Data.[[#This Row],[Categoría]]="Hunter",Data.[[#This Row],[Categoría]]="Senior"),OR(SUMIFS(AF:AF,H:H,Data.[[#This Row],[Ruc]],B:B,Data.[[#This Row],[Periodo]])>=15000,SUMIFS(AI:AI,H:H,Data.[[#This Row],[Ruc]],B:B,Data.[[#This Row],[Periodo]])>=15000,SUMIFS(AL:AL,H:H,Data.[[#This Row],[Ruc]],B:B,Data.[[#This Row],[Periodo]])>=15000,SUMIFS(AO:AO,H:H,Data.[[#This Row],[Ruc]],B:B,Data.[[#This Row],[Periodo]])>=15000)),AND(Data.[[#This Row],[Categoría]]="Elite",OR(SUMIFS(AF:AF,H:H,Data.[[#This Row],[Ruc]],B:B,Data.[[#This Row],[Periodo]])>=25000,SUMIFS(AI:AI,H:H,Data.[[#This Row],[Ruc]],B:B,Data.[[#This Row],[Periodo]])>=25000,SUMIFS(AL:AL,H:H,Data.[[#This Row],[Ruc]],B:B,Data.[[#This Row],[Periodo]])>=25000,SUMIFS(AO:AO,H:H,Data.[[#This Row],[Ruc]],B:B,Data.[[#This Row],[Periodo]])>=25000))),1,0)/COUNTIFS(H:H,Data.[[#This Row],[Ruc]],B:B,Data.[[#This Row],[Periodo]]),0) -> 0
A13: =CONCATENATE(Data.[[#This Row],[Código]],Data.[[#This Row],[Ruc]]) -> 594682710413980076 | B13: 46143 | C13: =IFERROR(VLOOKUP(Data.[[#This Row],[Código LT]],Reportería.[],71,0),"") | D13: =IFERROR(VLOOKUP(Data.[[#This Row],[Código]],BV!A:C,2,0),"") -> 46154 | E13: =IFERROR(VLOOKUP(Data.[[#This Row],[Código]],BV!A:C,3,0),"") -> 46155 | F13: 5946827 | G13: TJ33261920006 | H13: 10413980076 | I13: DAVALOS GUTIERREZ MIRIAN KARINA | J13: Arilustore | K13: =IF(Data.[[#This Row],[Tipo de Venta]]<>"POS","Atendido",IF(Data.[[#This Row],[Fecha de Instalación]]<>"","Atendido","Ingresado")) -> Atendido | L13: =Data.[[#This Row],[Estado]] -> Atendido | M13: POS | N13: =IFERROR(VLOOKUP(Data.[[#This Row],[Código LT]],Reportería.[],20,0),"") | O13: =IFERROR(VLOOKUP(Data.[[#This Row],[Código LT]],Reportería.[],5,0),"") | P13: =Data.[[#This Row],[GPV Mensual LT]]/COUNTIFS(H:H,Data.[[#This Row],[Ruc]],B:B,Data.[[#This Row],[Periodo]]) -> 25000 | Q13: 25000 | R13: Jonathan Lavado | S13: =VLOOKUP(Data.[[#This Row],[Ejecutivo]],Productividad!D:N,11,0) -> 41309076 | T13: =VLOOKUP(Data.[[#This Row],[DNI Ejecutivo]],Productividad!C:U,8,0) -> jonathan.lavado@lozapay.com.pe | U13: =VLOOKUP(Data.[[#This Row],[DNI Ejecutivo]],Productividad!C:U,4,0) -> Hunter | V13: =IFERROR(VLOOKUP(Data.[[#This Row],[DNI Ejecutivo]],Ejecutivos.[],11,0),"") -> Lima Jean | W13: Jean Aguilar | X13: {=IFERROR(_xlfn.IFS(Data.[[#This Row],[Supervisor]]="Jonathan Lapoint","Norte",Data.[[#This Row],[Supervisor]]="Jorge Fuentes","Norte"),"Lima")} -> Lima | Y13: =VLOOKUP(Data.[[#This Row],[Supervisor]],Ejecutivos!B:S,17,0) -> 47688341 | Z13: =VLOOKUP(Data.[[#This Row],[DNI Supervisor]],Productividad!C:U,8,0) -> jaguilar@lozapay.com.pe | AB13: JONATHAN ALEXANDER LAVADO CADERO | AC13: =IFERROR(CONCATENATE(Data.[[#This Row],[DNI Ejecutivo]],Data.[[#This Row],[Periodo]]),"") -> 4130907646143 | AD13: =IFERROR(VLOOKUP(Data.[[#This Row],[Código LT]],Reportería.[],10,0),"") | AE13: =IFERROR(VLOOKUP(Data.[[#This Row],[Código LT]],Reportería.[],11,0),"") | AF13: 486 | AI13: =IF(TEXT(Data.[[#This Row],[Periodo]],"mmm-yy")="may-26",VLOOKUP(Data.[[#This Row],[Código]],Reportería!A:BV,57,0),0) -> 976 | AL13: =IF(Data.[[#This Row],[Vol M0]]="",0,0) -> 0 | AM13: =IF(Data.[[#This Row],[Vol M0]]="",0,0) -> 0 | AN13: =IF(Data.[[#This Row],[Vol M0]]="",0,0) -> 0 | AO13: =IF(Data.[[#This Row],[Vol M0]]="",0,0) -> 0 | AP13: =IF(Data.[[#This Row],[Vol M0]]="",0,0) -> 0 | AQ13: =IF(Data.[[#This Row],[Vol M0]]="",0,0) -> 0 | AR13: =IFERROR(IF(OR(AND(OR(Data.[[#This Row],[Categoría]]="Hunter",Data.[[#This Row],[Categoría]]="Senior"),OR(SUMIFS(AF:AF,H:H,Data.[[#This Row],[Ruc]],B:B,Data.[[#This Row],[Periodo]])>=15000,SUMIFS(AI:AI,H:H,Data.[[#This Row],[Ruc]],B:B,Data.[[#This Row],[Periodo]])>=15000,SUMIFS(AL:AL,H:H,Data.[[#This Row],[Ruc]],B:B,Data.[[#This Row],[Periodo]])>=15000,SUMIFS(AO:AO,H:H,Data.[[#This Row],[Ruc]],B:B,Data.[[#This Row],[Periodo]])>=15000)),AND(Data.[[#This Row],[Categoría]]="Elite",OR(SUMIFS(AF:AF,H:H,Data.[[#This Row],[Ruc]],B:B,Data.[[#This Row],[Periodo]])>=25000,SUMIFS(AI:AI,H:H,Data.[[#This Row],[Ruc]],B:B,Data.[[#This Row],[Periodo]])>=25000,SUMIFS(AL:AL,H:H,Data.[[#This Row],[Ruc]],B:B,Data.[[#This Row],[Periodo]])>=25000,SUMIFS(AO:AO,H:H,Data.[[#This Row],[Ruc]],B:B,Data.[[#This Row],[Periodo]])>=25000))),1,0)/COUNTIFS(H:H,Data.[[#This Row],[Ruc]],B:B,Data.[[#This Row],[Periodo]]),0) -> 0
A14: =CONCATENATE(Data.[[#This Row],[Código]],Data.[[#This Row],[Ruc]]) -> 594764920614514338 | B14: 46143 | C14: =IFERROR(VLOOKUP(Data.[[#This Row],[Código LT]],Reportería.[],71,0),"") | D14: =IFERROR(VLOOKUP(Data.[[#This Row],[Código]],BV!A:C,2,0),"") -> 46156 | E14: =IFERROR(VLOOKUP(Data.[[#This Row],[Código]],BV!A:C,3,0),"") -> 46157 | F14: 5947649 | G14: TJ33261C21165 | H14: 20614514338 | I14: S. Y M. GRUPO CORPORACION INTERAMERICANA S.A.C. | J14: BRANS CHICKEN 1 | K14: =IF(Data.[[#This Row],[Tipo de Venta]]<>"POS","Atendido",IF(Data.[[#This Row],[Fecha de Instalación]]<>"","Atendido","Ingresado")) -> Atendido | L14: =Data.[[#This Row],[Estado]] -> Atendido | M14: POS | N14: =IFERROR(VLOOKUP(Data.[[#This Row],[Código LT]],Reportería.[],20,0),"") | O14: =IFERROR(VLOOKUP(Data.[[#This Row],[Código LT]],Reportería.[],5,0),"") | P14: =Data.[[#This Row],[GPV Mensual LT]]/COUNTIFS(H:H,Data.[[#This Row],[Ruc]],B:B,Data.[[#This Row],[Periodo]]) -> 25000 | Q14: 50000 | R14: Edinson Chuyes | S14: =VLOOKUP(Data.[[#This Row],[Ejecutivo]],Productividad!D:N,11,0) -> 45311691 | T14: =VLOOKUP(Data.[[#This Row],[DNI Ejecutivo]],Productividad!C:U,8,0) -> edinson.chuyes@lozapay.com.pe | U14: =VLOOKUP(Data.[[#This Row],[DNI Ejecutivo]],Productividad!C:U,4,0) -> Elite | V14: =IFERROR(VLOOKUP(Data.[[#This Row],[DNI Ejecutivo]],Ejecutivos.[],11,0),"") -> Lima Jean | W14: Jean Aguilar | X14: {=IFERROR(_xlfn.IFS(Data.[[#This Row],[Supervisor]]="Jonathan Lapoint","Norte",Data.[[#This Row],[Supervisor]]="Jorge Fuentes","Norte"),"Lima")} -> Lima | Y14: =VLOOKUP(Data.[[#This Row],[Supervisor]],Ejecutivos!B:S,17,0) -> 47688341 | Z14: =VLOOKUP(Data.[[#This Row],[DNI Supervisor]],Productividad!C:U,8,0) -> jaguilar@lozapay.com.pe | AB14: EDINSON WILLIAMS CHUYES ALDANA | AC14: =IFERROR(CONCATENATE(Data.[[#This Row],[DNI Ejecutivo]],Data.[[#This Row],[Periodo]]),"") -> 4531169146143 | AD14: =IFERROR(VLOOKUP(Data.[[#This Row],[Código LT]],Reportería.[],10,0),"") | AE14: =IFERROR(VLOOKUP(Data.[[#This Row],[Código LT]],Reportería.[],11,0),"") | AF14: 21455.5 | AI14: =IF(TEXT(Data.[[#This Row],[Periodo]],"mmm-yy")="may-26",VLOOKUP(Data.[[#This Row],[Código]],Reportería!A:BV,57,0),0) -> 14201.5 | AL14: =IF(Data.[[#This Row],[Vol M0]]="",0,0) -> 0 | AM14: =IF(Data.[[#This Row],[Vol M0]]="",0,0) -> 0 | AN14: =IF(Data.[[#This Row],[Vol M0]]="",0,0) -> 0 | AO14: =IF(Data.[[#This Row],[Vol M0]]="",0,0) -> 0 | AP14: =IF(Data.[[#This Row],[Vol M0]]="",0,0) -> 0 | AQ14: =IF(Data.[[#This Row],[Vol M0]]="",0,0) -> 0 | AR14: =IFERROR(IF(OR(AND(OR(Data.[[#This Row],[Categoría]]="Hunter",Data.[[#This Row],[Categoría]]="Senior"),OR(SUMIFS(AF:AF,H:H,Data.[[#This Row],[Ruc]],B:B,Data.[[#This Row],[Periodo]])>=15000,SUMIFS(AI:AI,H:H,Data.[[#This Row],[Ruc]],B:B,Data.[[#This Row],[Periodo]])>=15000,SUMIFS(AL:AL,H:H,Data.[[#This Row],[Ruc]],B:B,Data.[[#This Row],[Periodo]])>=15000,SUMIFS(AO:AO,H:H,Data.[[#This Row],[Ruc]],B:B,Data.[[#This Row],[Periodo]])>=15000)),AND(Data.[[#This Row],[Categoría]]="Elite",OR(SUMIFS(AF:AF,H:H,Data.[[#This Row],[Ruc]],B:B,Data.[[#This Row],[Periodo]])>=25000,SUMIFS(AI:AI,H:H,Data.[[#This Row],[Ruc]],B:B,Data.[[#This Row],[Periodo]])>=25000,SUMIFS(AL:AL,H:H,Data.[[#This Row],[Ruc]],B:B,Data.[[#This Row],[Periodo]])>=25000,SUMIFS(AO:AO,H:H,Data.[[#This Row],[Ruc]],B:B,Data.[[#This Row],[Periodo]])>=25000))),1,0)/COUNTIFS(H:H,Data.[[#This Row],[Ruc]],B:B,Data.[[#This Row],[Periodo]]),0) -> 0.5
A15: =CONCATENATE(Data.[[#This Row],[Código]],Data.[[#This Row],[Ruc]]) -> 594779320614514338 | B15: 46143 | C15: =IFERROR(VLOOKUP(Data.[[#This Row],[Código LT]],Reportería.[],71,0),"") | D15: =IFERROR(VLOOKUP(Data.[[#This Row],[Código]],BV!A:C,2,0),"") -> 46156 | E15: =IFERROR(VLOOKUP(Data.[[#This Row],[Código]],BV!A:C,3,0),"") -> 46160 | F15: 5947793 | G15: TJ33261C21512 | H15: 20614514338 | I15: S. Y M. GRUPO CORPORACION INTERAMERICANA S.A.C. | J15: BRANS CHICKEN 2 | K15: =IF(Data.[[#This Row],[Tipo de Venta]]<>"POS","Atendido",IF(Data.[[#This Row],[Fecha de Instalación]]<>"","Atendido","Ingresado")) -> Atendido | L15: =Data.[[#This Row],[Estado]] -> Atendido | M15: POS | N15: =IFERROR(VLOOKUP(Data.[[#This Row],[Código LT]],Reportería.[],20,0),"") | O15: =IFERROR(VLOOKUP(Data.[[#This Row],[Código LT]],Reportería.[],5,0),"") | P15: =Data.[[#This Row],[GPV Mensual LT]]/COUNTIFS(H:H,Data.[[#This Row],[Ruc]],B:B,Data.[[#This Row],[Periodo]]) -> 25000 | Q15: 50000 | R15: Edinson Chuyes | S15: =VLOOKUP(Data.[[#This Row],[Ejecutivo]],Productividad!D:N,11,0) -> 45311691 | T15: =VLOOKUP(Data.[[#This Row],[DNI Ejecutivo]],Productividad!C:U,8,0) -> edinson.chuyes@lozapay.com.pe | U15: =VLOOKUP(Data.[[#This Row],[DNI Ejecutivo]],Productividad!C:U,4,0) -> Elite | V15: =IFERROR(VLOOKUP(Data.[[#This Row],[DNI Ejecutivo]],Ejecutivos.[],11,0),"") -> Lima Jean | W15: Jean Aguilar | X15: {=IFERROR(_xlfn.IFS(Data.[[#This Row],[Supervisor]]="Jonathan Lapoint","Norte",Data.[[#This Row],[Supervisor]]="Jorge Fuentes","Norte"),"Lima")} -> Lima | Y15: =VLOOKUP(Data.[[#This Row],[Supervisor]],Ejecutivos!B:S,17,0) -> 47688341 | Z15: =VLOOKUP(Data.[[#This Row],[DNI Supervisor]],Productividad!C:U,8,0) -> jaguilar@lozapay.com.pe | AB15: EDINSON WILLIAMS CHUYES ALDANA | AC15: =IFERROR(CONCATENATE(Data.[[#This Row],[DNI Ejecutivo]],Data.[[#This Row],[Periodo]]),"") -> 4531169146143 | AD15: =IFERROR(VLOOKUP(Data.[[#This Row],[Código LT]],Reportería.[],10,0),"") | AE15: =IFERROR(VLOOKUP(Data.[[#This Row],[Código LT]],Reportería.[],11,0),"") | AF15: 14455 | AI15: =IF(TEXT(Data.[[#This Row],[Periodo]],"mmm-yy")="may-26",VLOOKUP(Data.[[#This Row],[Código]],Reportería!A:BV,57,0),0) -> 12849.5 | AL15: =IF(Data.[[#This Row],[Vol M0]]="",0,0) -> 0 | AM15: =IF(Data.[[#This Row],[Vol M0]]="",0,0) -> 0 | AN15: =IF(Data.[[#This Row],[Vol M0]]="",0,0) -> 0 | AO15: =IF(Data.[[#This Row],[Vol M0]]="",0,0) -> 0 | AP15: =IF(Data.[[#This Row],[Vol M0]]="",0,0) -> 0 | AQ15: =IF(Data.[[#This Row],[Vol M0]]="",0,0) -> 0 | AR15: =IFERROR(IF(OR(AND(OR(Data.[[#This Row],[Categoría]]="Hunter",Data.[[#This Row],[Categoría]]="Senior"),OR(SUMIFS(AF:AF,H:H,Data.[[#This Row],[Ruc]],B:B,Data.[[#This Row],[Periodo]])>=15000,SUMIFS(AI:AI,H:H,Data.[[#This Row],[Ruc]],B:B,Data.[[#This Row],[Periodo]])>=15000,SUMIFS(AL:AL,H:H,Data.[[#This Row],[Ruc]],B:B,Data.[[#This Row],[Periodo]])>=15000,SUMIFS(AO:AO,H:H,Data.[[#This Row],[Ruc]],B:B,Data.[[#This Row],[Periodo]])>=15000)),AND(Data.[[#This Row],[Categoría]]="Elite",OR(SUMIFS(AF:AF,H:H,Data.[[#This Row],[Ruc]],B:B,Data.[[#This Row],[Periodo]])>=25000,SUMIFS(AI:AI,H:H,Data.[[#This Row],[Ruc]],B:B,Data.[[#This Row],[Periodo]])>=25000,SUMIFS(AL:AL,H:H,Data.[[#This Row],[Ruc]],B:B,Data.[[#This Row],[Periodo]])>=25000,SUMIFS(AO:AO,H:H,Data.[[#This Row],[Ruc]],B:B,Data.[[#This Row],[Periodo]])>=25000))),1,0)/COUNTIFS(H:H,Data.[[#This Row],[Ruc]],B:B,Data.[[#This Row],[Periodo]]),0) -> 0.5
A16: =CONCATENATE(Data.[[#This Row],[Código]],Data.[[#This Row],[Ruc]]) -> 594765120612598780 | B16: 46143 | C16: =IFERROR(VLOOKUP(Data.[[#This Row],[Código LT]],Reportería.[],71,0),"") | D16: =IFERROR(VLOOKUP(Data.[[#This Row],[Código]],BV!A:C,2,0),"") -> 46157 | E16: =IFERROR(VLOOKUP(Data.[[#This Row],[Código]],BV!A:C,3,0),"") -> 46160 | F16: 5947651 | G16: TJ33261A20003 | H16: 20612598780 | I16: ANSOF COMPANY S.A.C.S. | J16: SAUNA TOKIO | K16: =IF(Data.[[#This Row],[Tipo de Venta]]<>"POS","Atendido",IF(Data.[[#This Row],[Fecha de Instalación]]<>"","Atendido","Ingresado")) -> Atendido | L16: =Data.[[#This Row],[Estado]] -> Atendido | M16: POS | N16: =IFERROR(VLOOKUP(Data.[[#This Row],[Código LT]],Reportería.[],20,0),"") | O16: =IFERROR(VLOOKUP(Data.[[#This Row],[Código LT]],Reportería.[],5,0),"") | P16: =Data.[[#This Row],[GPV Mensual LT]]/COUNTIFS(H:H,Data.[[#This Row],[Ruc]],B:B,Data.[[#This Row],[Periodo]]) -> 90000 | Q16: 180000 | R16: Maria Godoy | S16: =VLOOKUP(Data.[[#This Row],[Ejecutivo]],Productividad!D:N,11,0) -> 46998250 | T16: =VLOOKUP(Data.[[#This Row],[DNI Ejecutivo]],Productividad!C:U,8,0) -> mgodoyc@lozapay.com.pe | U16: =VLOOKUP(Data.[[#This Row],[DNI Ejecutivo]],Productividad!C:U,4,0) -> Elite | V16: =IFERROR(VLOOKUP(Data.[[#This Row],[DNI Ejecutivo]],Ejecutivos.[],11,0),"") -> Lima Palomino | W16: Carlos Palomino | X16: {=IFERROR(_xlfn.IFS(Data.[[#This Row],[Supervisor]]="Jonathan Lapoint","Norte",Data.[[#This Row],[Supervisor]]="Jorge Fuentes","Norte"),"Lima")} -> Lima | Y16: =VLOOKUP(Data.[[#This Row],[Supervisor]],Ejecutivos!B:S,17,0) -> 41718975 | Z16: =VLOOKUP(Data.[[#This Row],[DNI Supervisor]],Productividad!C:U,8,0) -> carlos.palomino@lozapay.com.pe | AB16: MARIA JOHANA GODOY CRUZ | AC16: =IFERROR(CONCATENATE(Data.[[#This Row],[DNI Ejecutivo]],Data.[[#This Row],[Periodo]]),"") -> 4699825046143 | AD16: =IFERROR(VLOOKUP(Data.[[#This Row],[Código LT]],Reportería.[],10,0),"") | AE16: =IFERROR(VLOOKUP(Data.[[#This Row],[Código LT]],Reportería.[],11,0),"") | AF16: 17809 | AI16: =IF(TEXT(Data.[[#This Row],[Periodo]],"mmm-yy")="may-26",VLOOKUP(Data.[[#This Row],[Código]],Reportería!A:BV,57,0),0) -> 19100 | AL16: =IF(Data.[[#This Row],[Vol M0]]="",0,0) -> 0 | AM16: =IF(Data.[[#This Row],[Vol M0]]="",0,0) -> 0 | AN16: =IF(Data.[[#This Row],[Vol M0]]="",0,0) -> 0 | AO16: =IF(Data.[[#This Row],[Vol M0]]="",0,0) -> 0 | AP16: =IF(Data.[[#This Row],[Vol M0]]="",0,0) -> 0 | AQ16: =IF(Data.[[#This Row],[Vol M0]]="",0,0) -> 0 | AR16: =IFERROR(IF(OR(AND(OR(Data.[[#This Row],[Categoría]]="Hunter",Data.[[#This Row],[Categoría]]="Senior"),OR(SUMIFS(AF:AF,H:H,Data.[[#This Row],[Ruc]],B:B,Data.[[#This Row],[Periodo]])>=15000,SUMIFS(AI:AI,H:H,Data.[[#This Row],[Ruc]],B:B,Data.[[#This Row],[Periodo]])>=15000,SUMIFS(AL:AL,H:H,Data.[[#This Row],[Ruc]],B:B,Data.[[#This Row],[Periodo]])>=15000,SUMIFS(AO:AO,H:H,Data.[[#This Row],[Ruc]],B:B,Data.[[#This Row],[Periodo]])>=15000)),AND(Data.[[#This Row],[Categoría]]="Elite",OR(SUMIFS(AF:AF,H:H,Data.[[#This Row],[Ruc]],B:B,Data.[[#This Row],[Periodo]])>=25000,SUMIFS(AI:AI,H:H,Data.[[#This Row],[Ruc]],B:B,Data.[[#This Row],[Periodo]])>=25000,SUMIFS(AL:AL,H:H,Data.[[#This Row],[Ruc]],B:B,Data.[[#This Row],[Periodo]])>=25000,SUMIFS(AO:AO,H:H,Data.[[#This Row],[Ruc]],B:B,Data.[[#This Row],[Periodo]])>=25000))),1,0)/COUNTIFS(H:H,Data.[[#This Row],[Ruc]],B:B,Data.[[#This Row],[Periodo]]),0) -> 0
A17: =CONCATENATE(Data.[[#This Row],[Código]],Data.[[#This Row],[Ruc]]) -> 594777520612598780 | B17: 46143 | C17: =IFERROR(VLOOKUP(Data.[[#This Row],[Código LT]],Reportería.[],71,0),"") | D17: =IFERROR(VLOOKUP(Data.[[#This Row],[Código]],BV!A:C,2,0),"") -> 46157 | E17: =IFERROR(VLOOKUP(Data.[[#This Row],[Código]],BV!A:C,3,0),"") -> 46160 | F17: 5947775 | G17: TJ33261A20244 | H17: 20612598780 | I17: ANSOF COMPANY S.A.C.S. | J17: SAUNA TOKIO | K17: =IF(Data.[[#This Row],[Tipo de Venta]]<>"POS","Atendido",IF(Data.[[#This Row],[Fecha de Instalación]]<>"","Atendido","Ingresado")) -> Atendido | L17: =Data.[[#This Row],[Estado]] -> Atendido | M17: POS | N17: =IFERROR(VLOOKUP(Data.[[#This Row],[Código LT]],Reportería.[],20,0),"") | O17: =IFERROR(VLOOKUP(Data.[[#This Row],[Código LT]],Reportería.[],5,0),"") | P17: =Data.[[#This Row],[GPV Mensual LT]]/COUNTIFS(H:H,Data.[[#This Row],[Ruc]],B:B,Data.[[#This Row],[Periodo]]) -> 90000 | Q17: 180000 | R17: Maria Godoy | S17: =VLOOKUP(Data.[[#This Row],[Ejecutivo]],Productividad!D:N,11,0) -> 46998250 | T17: =VLOOKUP(Data.[[#This Row],[DNI Ejecutivo]],Productividad!C:U,8,0) -> mgodoyc@lozapay.com.pe | U17: =VLOOKUP(Data.[[#This Row],[DNI Ejecutivo]],Productividad!C:U,4,0) -> Elite | V17: =IFERROR(VLOOKUP(Data.[[#This Row],[DNI Ejecutivo]],Ejecutivos.[],11,0),"") -> Lima Palomino | W17: Carlos Palomino | X17: {=IFERROR(_xlfn.IFS(Data.[[#This Row],[Supervisor]]="Jonathan Lapoint","Norte",Data.[[#This Row],[Supervisor]]="Jorge Fuentes","Norte"),"Lima")} -> Lima | Y17: =VLOOKUP(Data.[[#This Row],[Supervisor]],Ejecutivos!B:S,17,0) -> 41718975 | Z17: =VLOOKUP(Data.[[#This Row],[DNI Supervisor]],Productividad!C:U,8,0) -> carlos.palomino@lozapay.com.pe | AB17: MARIA JOHANA GODOY CRUZ | AC17: =IFERROR(CONCATENATE(Data.[[#This Row],[DNI Ejecutivo]],Data.[[#This Row],[Periodo]]),"") -> 4699825046143 | AD17: =IFERROR(VLOOKUP(Data.[[#This Row],[Código LT]],Reportería.[],10,0),"") | AE17: =IFERROR(VLOOKUP(Data.[[#This Row],[Código LT]],Reportería.[],11,0),"") | AF17: 2931 | AI17: =IF(TEXT(Data.[[#This Row],[Periodo]],"mmm-yy")="may-26",VLOOKUP(Data.[[#This Row],[Código]],Reportería!A:BV,57,0),0) -> 2844.9 | AL17: =IF(Data.[[#This Row],[Vol M0]]="",0,0) -> 0 | AM17: =IF(Data.[[#This Row],[Vol M0]]="",0,0) -> 0 | AN17: =IF(Data.[[#This Row],[Vol M0]]="",0,0) -> 0 | AO17: =IF(Data.[[#This Row],[Vol M0]]="",0,0) -> 0 | AP17: =IF(Data.[[#This Row],[Vol M0]]="",0,0) -> 0 | AQ17: =IF(Data.[[#This Row],[Vol M0]]="",0,0) -> 0 | AR17: =IFERROR(IF(OR(AND(OR(Data.[[#This Row],[Categoría]]="Hunter",Data.[[#This Row],[Categoría]]="Senior"),OR(SUMIFS(AF:AF,H:H,Data.[[#This Row],[Ruc]],B:B,Data.[[#This Row],[Periodo]])>=15000,SUMIFS(AI:AI,H:H,Data.[[#This Row],[Ruc]],B:B,Data.[[#This Row],[Periodo]])>=15000,SUMIFS(AL:AL,H:H,Data.[[#This Row],[Ruc]],B:B,Data.[[#This Row],[Periodo]])>=15000,SUMIFS(AO:AO,H:H,Data.[[#This Row],[Ruc]],B:B,Data.[[#This Row],[Periodo]])>=15000)),AND(Data.[[#This Row],[Categoría]]="Elite",OR(SUMIFS(AF:AF,H:H,Data.[[#This Row],[Ruc]],B:B,Data.[[#This Row],[Periodo]])>=25000,SUMIFS(AI:AI,H:H,Data.[[#This Row],[Ruc]],B:B,Data.[[#This Row],[Periodo]])>=25000,SUMIFS(AL:AL,H:H,Data.[[#This Row],[Ruc]],B:B,Data.[[#This Row],[Periodo]])>=25000,SUMIFS(AO:AO,H:H,Data.[[#This Row],[Ruc]],B:B,Data.[[#This Row],[Periodo]])>=25000))),1,0)/COUNTIFS(H:H,Data.[[#This Row],[Ruc]],B:B,Data.[[#This Row],[Periodo]]),0) -> 0
A18: =CONCATENATE(Data.[[#This Row],[Código]],Data.[[#This Row],[Ruc]]) -> 594769420615727165 | B18: 46143 | C18: =IFERROR(VLOOKUP(Data.[[#This Row],[Código LT]],Reportería.[],71,0),"") | D18: =IFERROR(VLOOKUP(Data.[[#This Row],[Código]],BV!A:C,2,0),"") -> 46157 | E18: =IFERROR(VLOOKUP(Data.[[#This Row],[Código]],BV!A:C,3,0),"") -> 46157 | F18: 5947694 | G18: TJ33261A21031 | H18: 20615727165 | I18: POLLERIAS B3 S.A.C. | J18: POWER GYM | K18: =IF(Data.[[#This Row],[Tipo de Venta]]<>"POS","Atendido",IF(Data.[[#This Row],[Fecha de Instalación]]<>"","Atendido","Ingresado")) -> Atendido | L18: =Data.[[#This Row],[Estado]] -> Atendido | M18: POS | N18: =IFERROR(VLOOKUP(Data.[[#This Row],[Código LT]],Reportería.[],20,0),"") | O18: =IFERROR(VLOOKUP(Data.[[#This Row],[Código LT]],Reportería.[],5,0),"") | P18: =Data.[[#This Row],[GPV Mensual LT]]/COUNTIFS(H:H,Data.[[#This Row],[Ruc]],B:B,Data.[[#This Row],[Periodo]]) -> 10000 | Q18: 10000 | R18: Guadalupe Del Pino | S18: =VLOOKUP(Data.[[#This Row],[Ejecutivo]],Productividad!D:N,11,0) -> 77016095 | T18: =VLOOKUP(Data.[[#This Row],[DNI Ejecutivo]],Productividad!C:U,8,0) -> nelly.delpino@lozapay.com.pe | U18: =VLOOKUP(Data.[[#This Row],[DNI Ejecutivo]],Productividad!C:U,4,0) -> Hunter | V18: =IFERROR(VLOOKUP(Data.[[#This Row],[DNI Ejecutivo]],Ejecutivos.[],11,0),"") -> Lima Jean | W18: Jean Aguilar | X18: {=IFERROR(_xlfn.IFS(Data.[[#This Row],[Supervisor]]="Jonathan Lapoint","Norte",Data.[[#This Row],[Supervisor]]="Jorge Fuentes","Norte"),"Lima")} -> Lima | Y18: =VLOOKUP(Data.[[#This Row],[Supervisor]],Ejecutivos!B:S,17,0) -> 47688341 | Z18: =VLOOKUP(Data.[[#This Row],[DNI Supervisor]],Productividad!C:U,8,0) -> jaguilar@lozapay.com.pe | AB18: NELLY GUADALUPE DEL PINO MONDRAGON | AC18: =IFERROR(CONCATENATE(Data.[[#This Row],[DNI Ejecutivo]],Data.[[#This Row],[Periodo]]),"") -> 7701609546143 | AD18: =IFERROR(VLOOKUP(Data.[[#This Row],[Código LT]],Reportería.[],10,0),"") | AE18: =IFERROR(VLOOKUP(Data.[[#This Row],[Código LT]],Reportería.[],11,0),"") | AF18: 3144.2 | AI18: =IF(TEXT(Data.[[#This Row],[Periodo]],"mmm-yy")="may-26",VLOOKUP(Data.[[#This Row],[Código]],Reportería!A:BV,57,0),0) -> 7190 | AL18: =IF(Data.[[#This Row],[Vol M0]]="",0,0) -> 0 | AM18: =IF(Data.[[#This Row],[Vol M0]]="",0,0) -> 0 | AN18: =IF(Data.[[#This Row],[Vol M0]]="",0,0) -> 0 | AO18: =IF(Data.[[#This Row],[Vol M0]]="",0,0) -> 0 | AP18: =IF(Data.[[#This Row],[Vol M0]]="",0,0) -> 0 | AQ18: =IF(Data.[[#This Row],[Vol M0]]="",0,0) -> 0 | AR18: =IFERROR(IF(OR(AND(OR(Data.[[#This Row],[Categoría]]="Hunter",Data.[[#This Row],[Categoría]]="Senior"),OR(SUMIFS(AF:AF,H:H,Data.[[#This Row],[Ruc]],B:B,Data.[[#This Row],[Periodo]])>=15000,SUMIFS(AI:AI,H:H,Data.[[#This Row],[Ruc]],B:B,Data.[[#This Row],[Periodo]])>=15000,SUMIFS(AL:AL,H:H,Data.[[#This Row],[Ruc]],B:B,Data.[[#This Row],[Periodo]])>=15000,SUMIFS(AO:AO,H:H,Data.[[#This Row],[Ruc]],B:B,Data.[[#This Row],[Periodo]])>=15000)),AND(Data.[[#This Row],[Categoría]]="Elite",OR(SUMIFS(AF:AF,H:H,Data.[[#This Row],[Ruc]],B:B,Data.[[#This Row],[Periodo]])>=25000,SUMIFS(AI:AI,H:H,Data.[[#This Row],[Ruc]],B:B,Data.[[#This Row],[Periodo]])>=25000,SUMIFS(AL:AL,H:H,Data.[[#This Row],[Ruc]],B:B,Data.[[#This Row],[Periodo]])>=25000,SUMIFS(AO:AO,H:H,Data.[[#This Row],[Ruc]],B:B,Data.[[#This Row],[Periodo]])>=25000))),1,0)/COUNTIFS(H:H,Data.[[#This Row],[Ruc]],B:B,Data.[[#This Row],[Periodo]]),0) -> 0
